2025-03-13 08:12:28,679 - log_util.py[DEBUG]: Cloud-init v. 24.4-0ubuntu1~22.04.1 running 'init-local' at Thu, 13 Mar 2025 08:12:28 +0000. Up 5.78 seconds.
2025-03-13 08:12:28,679 - main.py[INFO]: PID [1] started cloud-init 'init-local'.
2025-03-13 08:12:28,679 - main.py[DEBUG]: No kernel command line url found.
2025-03-13 08:12:28,679 - main.py[DEBUG]: Closing stdin
2025-03-13 08:12:28,682 - util.py[DEBUG]: Writing to /var/log/cloud-init.log - ab: [640] 0 bytes
2025-03-13 08:12:28,692 - util.py[DEBUG]: Changing the ownership of /var/log/cloud-init.log to 104:4
2025-03-13 08:12:28,692 - util.py[DEBUG]: Writing to /var/lib/cloud/data/python-version - wb: [644] 4 bytes
2025-03-13 08:12:28,699 - util.py[DEBUG]: Attempting to remove /var/lib/cloud/instance/boot-finished
2025-03-13 08:12:28,699 - handlers.py[DEBUG]: start: init-local/check-cache: attempting to read from cache [check]
2025-03-13 08:12:28,699 - util.py[DEBUG]: Reading from /var/lib/cloud/instance/obj.pkl (quiet=False)
2025-03-13 08:12:28,699 - stages.py[DEBUG]: no cache found
2025-03-13 08:12:28,699 - handlers.py[DEBUG]: finish: init-local/check-cache: SUCCESS: no cache found
2025-03-13 08:12:28,707 - stages.py[DEBUG]: Using distro class <class 'cloudinit.distros.ubuntu.Distro'>
2025-03-13 08:12:28,707 - sources[DEBUG]: Looking for data source in: ['Akamai', 'None'], via packages ['', 'cloudinit.sources'] that matches dependencies ['FILESYSTEM']
2025-03-13 08:12:28,718 - sources[DEBUG]: Searching for local data source in: ['DataSourceAkamaiLocal']
2025-03-13 08:12:28,718 - handlers.py[DEBUG]: start: init-local/search-AkamaiLocal: searching for local data from DataSourceAkamaiLocal
2025-03-13 08:12:28,718 - sources[DEBUG]: Seeing if we can get any data from <class 'cloudinit.sources.DataSourceAkamai.DataSourceAkamaiLocal'>
2025-03-13 08:12:28,718 - DataSourceAkamai.py[DEBUG]: Setting up Akamai DataSource
2025-03-13 08:12:28,718 - dmi.py[DEBUG]: querying dmi data /sys/class/dmi/id/board_serial
2025-03-13 08:12:28,719 - dmi.py[DEBUG]: did not find /sys/class/dmi/id/board_serial
2025-03-13 08:12:28,719 - subp.py[DEBUG]: Running command ['/usr/sbin/dmidecode', '--string', 'baseboard-serial-number'] with allowed return codes [0] (shell=False, capture=True)
2025-03-13 08:12:28,723 - dmi.py[DEBUG]: dmidecode returned '' for 'baseboard-serial-number'
2025-03-13 08:12:28,723 - sources[DEBUG]: Update datasource metadata and network config due to events: boot-new-instance
2025-03-13 08:12:28,724 - sources[DEBUG]: Detected DataSourceAkamaiLocal
2025-03-13 08:12:28,724 - DataSourceAkamai.py[DEBUG]: Getting data from Akamai DataSource
2025-03-13 08:12:28,724 - dmi.py[DEBUG]: querying dmi data /sys/class/dmi/id/sys_vendor
2025-03-13 08:12:28,724 - dmi.py[DEBUG]: querying dmi data /sys/class/dmi/id/product_serial
2025-03-13 08:12:28,724 - util.py[DEBUG]: Reading from /sys/class/net/eth0/addr_assign_type (quiet=False)
2025-03-13 08:12:28,724 - util.py[DEBUG]: Reading 2 bytes from /sys/class/net/eth0/addr_assign_type
2025-03-13 08:12:28,724 - util.py[DEBUG]: Reading from /sys/class/net/eth0/uevent (quiet=False)
2025-03-13 08:12:28,724 - util.py[DEBUG]: Reading 25 bytes from /sys/class/net/eth0/uevent
2025-03-13 08:12:28,725 - util.py[DEBUG]: Reading from /sys/class/net/eth0/address (quiet=False)
2025-03-13 08:12:28,725 - util.py[DEBUG]: Reading 18 bytes from /sys/class/net/eth0/address
2025-03-13 08:12:28,725 - net[DEBUG]: ovs-vsctl not in PATH; not detecting Open vSwitch interfaces
2025-03-13 08:12:28,725 - util.py[DEBUG]: Reading from /sys/class/net/eth0/device/device (quiet=False)
2025-03-13 08:12:28,725 - util.py[DEBUG]: Reading 7 bytes from /sys/class/net/eth0/device/device
2025-03-13 08:12:28,725 - util.py[DEBUG]: Reading from /sys/class/net/lo/addr_assign_type (quiet=False)
2025-03-13 08:12:28,725 - util.py[DEBUG]: Reading 2 bytes from /sys/class/net/lo/addr_assign_type
2025-03-13 08:12:28,725 - util.py[DEBUG]: Reading from /sys/class/net/lo/uevent (quiet=False)
2025-03-13 08:12:28,725 - util.py[DEBUG]: Reading 23 bytes from /sys/class/net/lo/uevent
2025-03-13 08:12:28,725 - util.py[DEBUG]: Reading from /sys/class/net/lo/address (quiet=False)
2025-03-13 08:12:28,725 - util.py[DEBUG]: Reading 18 bytes from /sys/class/net/lo/address
2025-03-13 08:12:28,725 - util.py[DEBUG]: Reading from /sys/class/net/lo/device/device (quiet=False)
2025-03-13 08:12:28,726 - util.py[DEBUG]: Reading from /sys/class/net/eth0/type (quiet=False)
2025-03-13 08:12:28,726 - util.py[DEBUG]: Reading 2 bytes from /sys/class/net/eth0/type
2025-03-13 08:12:28,726 - util.py[DEBUG]: Reading from /sys/class/net/lo/type (quiet=False)
2025-03-13 08:12:28,726 - util.py[DEBUG]: Reading 4 bytes from /sys/class/net/lo/type
2025-03-13 08:12:28,726 - ephemeral.py[DEBUG]: No connectivity URLs provided. Skipping connectivity check before ephemeral network setup.
2025-03-13 08:12:28,726 - ephemeral.py[DEBUG]: No connectivity to IMDS, attempting DHCP setup.
2025-03-13 08:12:28,726 - util.py[DEBUG]: Reading from /sys/class/net/eth0/operstate (quiet=False)
2025-03-13 08:12:28,726 - util.py[DEBUG]: Reading 5 bytes from /sys/class/net/eth0/operstate
2025-03-13 08:12:28,726 - subp.py[DEBUG]: Running command ['ip', 'link', 'set', 'dev', 'eth0', 'up'] with allowed return codes [0] (shell=False, capture=True)
2025-03-13 08:12:28,741 - performance.py[DEBUG]: Running ['ip', 'link', 'set', 'dev', 'eth0', 'up'] took 0.015 seconds
2025-03-13 08:12:28,741 - ephemeral.py[DEBUG]: Successfully brought up eth0 for ephemeral ipv6 networking.
2025-03-13 08:12:28,742 - url_helper.py[DEBUG]: [0/5] open 'http://[fd00:a9fe:a9fe::1]/v1/token' with {'url': 'http://[fd00:a9fe:a9fe::1]/v1/token', 'stream': False, 'allow_redirects': True, 'method': 'PUT', 'timeout': 30.0, 'headers': {'Metadata-Token-Expiry-Seconds': '300', 'User-Agent': 'Cloud-Init/24.4-0ubuntu1~22.04.1'}} configuration
2025-03-13 08:12:28,749 - url_helper.py[DEBUG]: Please wait 2 seconds while we wait to try again
2025-03-13 08:12:30,750 - url_helper.py[DEBUG]: [1/5] open 'http://[fd00:a9fe:a9fe::1]/v1/token' with {'url': 'http://[fd00:a9fe:a9fe::1]/v1/token', 'stream': False, 'allow_redirects': True, 'method': 'PUT', 'timeout': 30.0, 'headers': {'Metadata-Token-Expiry-Seconds': '300', 'User-Agent': 'Cloud-Init/24.4-0ubuntu1~22.04.1'}} configuration
2025-03-13 08:12:30,752 - url_helper.py[DEBUG]: Please wait 2 seconds while we wait to try again
2025-03-13 08:12:32,754 - url_helper.py[DEBUG]: [2/5] open 'http://[fd00:a9fe:a9fe::1]/v1/token' with {'url': 'http://[fd00:a9fe:a9fe::1]/v1/token', 'stream': False, 'allow_redirects': True, 'method': 'PUT', 'timeout': 30.0, 'headers': {'Metadata-Token-Expiry-Seconds': '300', 'User-Agent': 'Cloud-Init/24.4-0ubuntu1~22.04.1'}} configuration
2025-03-13 08:12:33,167 - url_helper.py[DEBUG]: Read from http://[fd00:a9fe:a9fe::1]/v1/token (200, 64b) after 3 attempts
2025-03-13 08:12:33,167 - url_helper.py[DEBUG]: [0/3] open 'http://[fd00:a9fe:a9fe::1]/v1/instance' with {'url': 'http://[fd00:a9fe:a9fe::1]/v1/instance', 'stream': False, 'allow_redirects': True, 'method': 'GET', 'timeout': 30.0, 'headers': {'Accept': 'application/json', 'Metadata-Token': '2a91c532a8ce428e32d0405c4a69bdc3d0973ff5e46aaf292cf84ba6317780bc', 'User-Agent': 'Cloud-Init/24.4-0ubuntu1~22.04.1'}} configuration
2025-03-13 08:12:34,105 - url_helper.py[DEBUG]: Read from http://[fd00:a9fe:a9fe::1]/v1/instance (200, 409b) after 1 attempts
2025-03-13 08:12:34,106 - url_helper.py[DEBUG]: [0/3] open 'http://[fd00:a9fe:a9fe::1]/v1/user-data' with {'url': 'http://[fd00:a9fe:a9fe::1]/v1/user-data', 'stream': False, 'allow_redirects': True, 'method': 'GET', 'timeout': 30.0, 'headers': {'Metadata-Token': '2a91c532a8ce428e32d0405c4a69bdc3d0973ff5e46aaf292cf84ba6317780bc', 'User-Agent': 'Cloud-Init/24.4-0ubuntu1~22.04.1'}} configuration
2025-03-13 08:12:34,620 - url_helper.py[DEBUG]: Read from http://[fd00:a9fe:a9fe::1]/v1/user-data (200, 0b) after 1 attempts
2025-03-13 08:12:34,621 - util.py[DEBUG]: Reading from /etc/hosts (quiet=False)
2025-03-13 08:12:34,621 - util.py[DEBUG]: Reading 181 bytes from /etc/hosts
2025-03-13 08:12:34,622 - util.py[DEBUG]: Writing to /run/cloud-init/cloud-id-akamai - wb: [644] 7 bytes
2025-03-13 08:12:34,622 - util.py[DEBUG]: Creating symbolic link from '/run/cloud-init/cloud-id' => '/run/cloud-init/cloud-id-akamai'
2025-03-13 08:12:34,623 - atomic_helper.py[DEBUG]: Atomically writing to file /run/cloud-init/instance-data-sensitive.json (via temporary file /run/cloud-init/tmpo2ekg3qf) - w: [600] 8728 bytes/chars
2025-03-13 08:12:34,623 - atomic_helper.py[DEBUG]: Atomically writing to file /run/cloud-init/instance-data.json (via temporary file /run/cloud-init/tmpoit2fr57) - w: [644] 1943 bytes/chars
2025-03-13 08:12:34,624 - performance.py[DEBUG]: Getting metadata took 5.900 seconds
2025-03-13 08:12:34,624 - handlers.py[DEBUG]: finish: init-local/search-AkamaiLocal: SUCCESS: found local data from DataSourceAkamaiLocal
2025-03-13 08:12:34,624 - util.py[DEBUG]: Attempting to remove /var/lib/cloud/instance
2025-03-13 08:12:34,624 - stages.py[INFO]: Loaded datasource DataSourceAkamaiLocal - DataSourceAkamaiLocal
2025-03-13 08:12:34,624 - util.py[DEBUG]: Reading from /etc/cloud/cloud.cfg (quiet=False)
2025-03-13 08:12:34,624 - util.py[DEBUG]: Reading 3766 bytes from /etc/cloud/cloud.cfg
2025-03-13 08:12:34,624 - util.py[DEBUG]: Attempting to load yaml from string of length 3766 with allowed root types (<class 'dict'>,)
2025-03-13 08:12:34,636 - util.py[DEBUG]: Reading from /etc/cloud/cloud.cfg.d/99-linode.cfg (quiet=False)
2025-03-13 08:12:34,636 - util.py[DEBUG]: Reading 492 bytes from /etc/cloud/cloud.cfg.d/99-linode.cfg
2025-03-13 08:12:34,636 - util.py[DEBUG]: Attempting to load yaml from string of length 492 with allowed root types (<class 'dict'>,)
2025-03-13 08:12:34,638 - util.py[DEBUG]: Reading from /etc/cloud/cloud.cfg.d/90_dpkg.cfg (quiet=False)
2025-03-13 08:12:34,638 - util.py[DEBUG]: Reading 333 bytes from /etc/cloud/cloud.cfg.d/90_dpkg.cfg
2025-03-13 08:12:34,638 - util.py[DEBUG]: Attempting to load yaml from string of length 333 with allowed root types (<class 'dict'>,)
2025-03-13 08:12:34,640 - util.py[DEBUG]: Reading from /etc/cloud/cloud.cfg.d/05_logging.cfg (quiet=False)
2025-03-13 08:12:34,640 - util.py[DEBUG]: Reading 2071 bytes from /etc/cloud/cloud.cfg.d/05_logging.cfg
2025-03-13 08:12:34,640 - util.py[DEBUG]: Attempting to load yaml from string of length 2071 with allowed root types (<class 'dict'>,)
2025-03-13 08:12:34,644 - util.py[DEBUG]: Reading from /run/cloud-init/cloud.cfg (quiet=False)
2025-03-13 08:12:34,644 - util.py[DEBUG]: Reading 34 bytes from /run/cloud-init/cloud.cfg
2025-03-13 08:12:34,644 - util.py[DEBUG]: Attempting to load yaml from string of length 34 with allowed root types (<class 'dict'>,)
2025-03-13 08:12:34,644 - util.py[DEBUG]: Attempting to load yaml from string of length 0 with allowed root types (<class 'dict'>,)
2025-03-13 08:12:34,644 - util.py[DEBUG]: loaded blob returned None, returning default.
2025-03-13 08:12:34,645 - util.py[DEBUG]: Attempting to remove /var/lib/cloud/instance
2025-03-13 08:12:34,645 - util.py[DEBUG]: Creating symbolic link from '/var/lib/cloud/instance' => '/var/lib/cloud/instances/73502904'
2025-03-13 08:12:34,647 - util.py[DEBUG]: Reading from /var/lib/cloud/instances/73502904/datasource (quiet=False)
2025-03-13 08:12:34,647 - util.py[DEBUG]: Writing to /var/lib/cloud/instances/73502904/datasource - wb: [644] 45 bytes
2025-03-13 08:12:34,647 - util.py[DEBUG]: Writing to /var/lib/cloud/data/previous-datasource - wb: [644] 45 bytes
2025-03-13 08:12:34,647 - util.py[DEBUG]: Reading from /var/lib/cloud/data/instance-id (quiet=False)
2025-03-13 08:12:34,647 - stages.py[DEBUG]: previous iid found to be NO_PREVIOUS_INSTANCE_ID
2025-03-13 08:12:34,647 - util.py[DEBUG]: Writing to /var/lib/cloud/data/instance-id - wb: [644] 9 bytes
2025-03-13 08:12:34,648 - util.py[DEBUG]: Writing to /run/cloud-init/.instance-id - wb: [644] 9 bytes
2025-03-13 08:12:34,648 - util.py[DEBUG]: Writing to /var/lib/cloud/data/previous-instance-id - wb: [644] 24 bytes
2025-03-13 08:12:34,649 - util.py[DEBUG]: Writing to /var/lib/cloud/instance/obj.pkl - wb: [400] 7028 bytes
2025-03-13 08:12:34,649 - main.py[DEBUG]: [local] init will now be targeting instance id: 73502904. new=True
2025-03-13 08:12:34,649 - util.py[DEBUG]: Reading from /etc/cloud/cloud.cfg (quiet=False)
2025-03-13 08:12:34,649 - util.py[DEBUG]: Reading 3766 bytes from /etc/cloud/cloud.cfg
2025-03-13 08:12:34,649 - util.py[DEBUG]: Attempting to load yaml from string of length 3766 with allowed root types (<class 'dict'>,)
2025-03-13 08:12:34,661 - util.py[DEBUG]: Reading from /etc/cloud/cloud.cfg.d/99-linode.cfg (quiet=False)
2025-03-13 08:12:34,661 - util.py[DEBUG]: Reading 492 bytes from /etc/cloud/cloud.cfg.d/99-linode.cfg
2025-03-13 08:12:34,661 - util.py[DEBUG]: Attempting to load yaml from string of length 492 with allowed root types (<class 'dict'>,)
2025-03-13 08:12:34,663 - util.py[DEBUG]: Reading from /etc/cloud/cloud.cfg.d/90_dpkg.cfg (quiet=False)
2025-03-13 08:12:34,663 - util.py[DEBUG]: Reading 333 bytes from /etc/cloud/cloud.cfg.d/90_dpkg.cfg
2025-03-13 08:12:34,663 - util.py[DEBUG]: Attempting to load yaml from string of length 333 with allowed root types (<class 'dict'>,)
2025-03-13 08:12:34,665 - util.py[DEBUG]: Reading from /etc/cloud/cloud.cfg.d/05_logging.cfg (quiet=False)
2025-03-13 08:12:34,665 - util.py[DEBUG]: Reading 2071 bytes from /etc/cloud/cloud.cfg.d/05_logging.cfg
2025-03-13 08:12:34,665 - util.py[DEBUG]: Attempting to load yaml from string of length 2071 with allowed root types (<class 'dict'>,)
2025-03-13 08:12:34,669 - util.py[DEBUG]: Reading from /run/cloud-init/cloud.cfg (quiet=False)
2025-03-13 08:12:34,669 - util.py[DEBUG]: Reading 34 bytes from /run/cloud-init/cloud.cfg
2025-03-13 08:12:34,669 - util.py[DEBUG]: Attempting to load yaml from string of length 34 with allowed root types (<class 'dict'>,)
2025-03-13 08:12:34,669 - util.py[DEBUG]: Attempting to load yaml from string of length 0 with allowed root types (<class 'dict'>,)
2025-03-13 08:12:34,669 - util.py[DEBUG]: loaded blob returned None, returning default.
2025-03-13 08:12:34,671 - stages.py[DEBUG]: Using distro class <class 'cloudinit.distros.ubuntu.Distro'>
2025-03-13 08:12:34,672 - util.py[DEBUG]: Reading from /sys/class/net/eth0/address (quiet=False)
2025-03-13 08:12:34,672 - util.py[DEBUG]: Reading 18 bytes from /sys/class/net/eth0/address
2025-03-13 08:12:34,672 - util.py[DEBUG]: Reading from /sys/class/net/lo/address (quiet=False)
2025-03-13 08:12:34,672 - util.py[DEBUG]: Reading 18 bytes from /sys/class/net/lo/address
2025-03-13 08:12:34,672 - stages.py[DEBUG]: network config disabled by system_cfg
2025-03-13 08:12:34,672 - stages.py[INFO]: network config is disabled by system_cfg
2025-03-13 08:12:34,672 - main.py[DEBUG]: Network connectivity determined unnecessary for cloud-init's network stage. Reason: user data: no configuration found, vendor data: no configuration found, vendor data2: no configuration found
2025-03-13 08:12:34,672 - util.py[DEBUG]: Writing to /run/cloud-init/.skip-network - wb: [644] 0 bytes
2025-03-13 08:12:34,673 - main.py[DEBUG]: [local] Exiting. datasource DataSourceAkamaiLocal not in local mode.
2025-03-13 08:12:34,673 - util.py[DEBUG]: Reading from /proc/uptime (quiet=False)
2025-03-13 08:12:34,673 - util.py[DEBUG]: Reading 11 bytes from /proc/uptime
2025-03-13 08:12:34,673 - atomic_helper.py[DEBUG]: Atomically writing to file /var/lib/cloud/data/status.json (via temporary file /var/lib/cloud/data/tmpwvkq_jde) - w: [644] 503 bytes/chars
2025-03-13 08:12:34,673 - performance.py[DEBUG]: cloud-init stage: 'init-local' took 6.176 seconds
2025-03-13 08:12:34,673 - handlers.py[DEBUG]: finish: init-local: SUCCESS: searching for local datasources
2025-03-13 08:12:38,093 - log_util.py[DEBUG]: Cloud-init v. 24.4-0ubuntu1~22.04.1 running 'init' at Thu, 13 Mar 2025 08:12:38 +0000. Up 15.26 seconds.
2025-03-13 08:12:38,093 - main.py[INFO]: PID [1] started cloud-init 'init'.
2025-03-13 08:12:38,093 - main.py[DEBUG]: No kernel command line url found.
2025-03-13 08:12:38,093 - main.py[DEBUG]: Closing stdin
2025-03-13 08:12:38,095 - util.py[DEBUG]: Writing to /var/log/cloud-init.log - ab: [640] 0 bytes
2025-03-13 08:12:38,096 - util.py[DEBUG]: Changing the ownership of /var/log/cloud-init.log to 104:4
2025-03-13 08:12:38,096 - util.py[DEBUG]: Reading from /var/lib/cloud/data/python-version (quiet=False)
2025-03-13 08:12:38,096 - util.py[DEBUG]: Reading 4 bytes from /var/lib/cloud/data/python-version
2025-03-13 08:12:38,096 - subp.py[DEBUG]: Running command ['ip', '--json', 'addr'] with allowed return codes [0] (shell=False, capture=True)
2025-03-13 08:12:38,103 - subp.py[DEBUG]: Running command ['ip', '-o', 'route', 'list'] with allowed return codes [0] (shell=False, capture=True)
2025-03-13 08:12:38,105 - subp.py[DEBUG]: Running command ['ip', '--oneline', '-6', 'route', 'list', 'table', 'all'] with allowed return codes [0, 1] (shell=False, capture=True)
2025-03-13 08:12:38,107 - handlers.py[DEBUG]: start: init-network/check-cache: attempting to read from cache [trust]
2025-03-13 08:12:38,107 - util.py[DEBUG]: Reading from /var/lib/cloud/instance/obj.pkl (quiet=False)
2025-03-13 08:12:38,107 - util.py[DEBUG]: Reading 7028 bytes from /var/lib/cloud/instance/obj.pkl
2025-03-13 08:12:38,110 - util.py[DEBUG]: Reading from /run/cloud-init/.instance-id (quiet=False)
2025-03-13 08:12:38,110 - util.py[DEBUG]: Reading 9 bytes from /run/cloud-init/.instance-id
2025-03-13 08:12:38,110 - stages.py[DEBUG]: restored from cache with run check: DataSourceAkamaiLocal
2025-03-13 08:12:38,110 - handlers.py[DEBUG]: finish: init-network/check-cache: SUCCESS: restored from cache with run check: DataSourceAkamaiLocal
2025-03-13 08:12:38,114 - util.py[DEBUG]: Reading from /etc/cloud/cloud.cfg (quiet=False)
2025-03-13 08:12:38,114 - util.py[DEBUG]: Reading 3766 bytes from /etc/cloud/cloud.cfg
2025-03-13 08:12:38,114 - util.py[DEBUG]: Attempting to load yaml from string of length 3766 with allowed root types (<class 'dict'>,)
2025-03-13 08:12:38,141 - util.py[DEBUG]: Reading from /etc/cloud/cloud.cfg.d/99-linode.cfg (quiet=False)
2025-03-13 08:12:38,141 - util.py[DEBUG]: Reading 492 bytes from /etc/cloud/cloud.cfg.d/99-linode.cfg
2025-03-13 08:12:38,141 - util.py[DEBUG]: Attempting to load yaml from string of length 492 with allowed root types (<class 'dict'>,)
2025-03-13 08:12:38,145 - util.py[DEBUG]: Reading from /etc/cloud/cloud.cfg.d/90_dpkg.cfg (quiet=False)
2025-03-13 08:12:38,145 - util.py[DEBUG]: Reading 333 bytes from /etc/cloud/cloud.cfg.d/90_dpkg.cfg
2025-03-13 08:12:38,145 - util.py[DEBUG]: Attempting to load yaml from string of length 333 with allowed root types (<class 'dict'>,)
2025-03-13 08:12:38,149 - util.py[DEBUG]: Reading from /etc/cloud/cloud.cfg.d/05_logging.cfg (quiet=False)
2025-03-13 08:12:38,149 - util.py[DEBUG]: Reading 2071 bytes from /etc/cloud/cloud.cfg.d/05_logging.cfg
2025-03-13 08:12:38,149 - util.py[DEBUG]: Attempting to load yaml from string of length 2071 with allowed root types (<class 'dict'>,)
2025-03-13 08:12:38,158 - util.py[DEBUG]: Reading from /run/cloud-init/cloud.cfg (quiet=False)
2025-03-13 08:12:38,158 - util.py[DEBUG]: Reading 34 bytes from /run/cloud-init/cloud.cfg
2025-03-13 08:12:38,158 - util.py[DEBUG]: Attempting to load yaml from string of length 34 with allowed root types (<class 'dict'>,)
2025-03-13 08:12:38,158 - util.py[DEBUG]: Attempting to load yaml from string of length 0 with allowed root types (<class 'dict'>,)
2025-03-13 08:12:38,158 - util.py[DEBUG]: loaded blob returned None, returning default.
2025-03-13 08:12:38,159 - stages.py[INFO]: Instance link already exists, not recreating it.
2025-03-13 08:12:38,160 - util.py[DEBUG]: Reading from /var/lib/cloud/instances/73502904/datasource (quiet=False)
2025-03-13 08:12:38,160 - util.py[DEBUG]: Reading 45 bytes from /var/lib/cloud/instances/73502904/datasource
2025-03-13 08:12:38,160 - util.py[DEBUG]: Writing to /var/lib/cloud/instances/73502904/datasource - wb: [644] 45 bytes
2025-03-13 08:12:38,162 - util.py[DEBUG]: Writing to /var/lib/cloud/data/previous-datasource - wb: [644] 45 bytes
2025-03-13 08:12:38,162 - util.py[DEBUG]: Reading from /var/lib/cloud/data/instance-id (quiet=False)
2025-03-13 08:12:38,162 - util.py[DEBUG]: Reading 9 bytes from /var/lib/cloud/data/instance-id
2025-03-13 08:12:38,162 - stages.py[DEBUG]: previous iid found to be 73502904
2025-03-13 08:12:38,163 - util.py[DEBUG]: Writing to /var/lib/cloud/data/instance-id - wb: [644] 9 bytes
2025-03-13 08:12:38,165 - util.py[DEBUG]: Writing to /run/cloud-init/.instance-id - wb: [644] 9 bytes
2025-03-13 08:12:38,165 - util.py[DEBUG]: Writing to /var/lib/cloud/data/previous-instance-id - wb: [644] 9 bytes
2025-03-13 08:12:38,166 - util.py[DEBUG]: Writing to /var/lib/cloud/instance/obj.pkl - wb: [400] 7040 bytes
2025-03-13 08:12:38,166 - stages.py[INFO]: Not re-loading configuration, instance id and datasource have not changed.
2025-03-13 08:12:38,166 - main.py[DEBUG]: [net] init will now be targeting instance id: 73502904. new=False
2025-03-13 08:12:38,167 - util.py[DEBUG]: Reading from /sys/class/net/eth0/address (quiet=False)
2025-03-13 08:12:38,167 - util.py[DEBUG]: Reading 18 bytes from /sys/class/net/eth0/address
2025-03-13 08:12:38,167 - util.py[DEBUG]: Reading from /sys/class/net/lo/address (quiet=False)
2025-03-13 08:12:38,167 - util.py[DEBUG]: Reading 18 bytes from /sys/class/net/lo/address
2025-03-13 08:12:38,167 - stages.py[DEBUG]: network config disabled by system_cfg
2025-03-13 08:12:38,167 - stages.py[INFO]: network config is disabled by system_cfg
2025-03-13 08:12:38,168 - handlers.py[DEBUG]: start: init-network/setup-datasource: setting up datasource
2025-03-13 08:12:38,168 - handlers.py[DEBUG]: finish: init-network/setup-datasource: SUCCESS: setting up datasource
2025-03-13 08:12:38,168 - util.py[DEBUG]: Writing to /var/lib/cloud/instances/73502904/user-data.txt - wb: [600] 0 bytes
2025-03-13 08:12:38,173 - util.py[DEBUG]: Writing to /var/lib/cloud/instances/73502904/user-data.txt.i - wb: [600] 308 bytes
2025-03-13 08:12:38,173 - util.py[DEBUG]: Writing to /var/lib/cloud/instances/73502904/vendor-data.txt - wb: [600] 0 bytes
2025-03-13 08:12:38,174 - util.py[DEBUG]: Writing to /var/lib/cloud/instances/73502904/vendor-data.txt.i - wb: [600] 308 bytes
2025-03-13 08:12:38,174 - util.py[DEBUG]: Writing to /var/lib/cloud/instances/73502904/vendor-data2.txt - wb: [600] 0 bytes
2025-03-13 08:12:38,178 - util.py[DEBUG]: Writing to /var/lib/cloud/instances/73502904/vendor-data2.txt.i - wb: [600] 308 bytes
2025-03-13 08:12:38,180 - stages.py[DEBUG]: Using distro class <class 'cloudinit.distros.ubuntu.Distro'>
2025-03-13 08:12:38,181 - util.py[DEBUG]: Writing to /var/lib/cloud/instances/73502904/sem/consume_data - wb: [644] 23 bytes
2025-03-13 08:12:38,181 - helpers.py[DEBUG]: Running consume_data using lock (<FileLock using file '/var/lib/cloud/instances/73502904/sem/consume_data'>)
2025-03-13 08:12:38,181 - handlers.py[DEBUG]: start: init-network/consume-user-data: reading and applying user-data
2025-03-13 08:12:38,182 - stages.py[DEBUG]: Added default handler for {'text/cloud-config', 'text/cloud-config-jsonp'} from CloudConfigPartHandler: [['text/cloud-config', 'text/cloud-config-jsonp']]
2025-03-13 08:12:38,182 - stages.py[DEBUG]: Added default handler for {'text/x-shellscript'} from ShellScriptPartHandler: [['text/x-shellscript']]
2025-03-13 08:12:38,182 - stages.py[DEBUG]: Added default handler for {'text/x-shellscript-per-boot'} from ShellScriptByFreqPartHandler: [['text/x-shellscript-per-boot']]
2025-03-13 08:12:38,182 - stages.py[DEBUG]: Added default handler for {'text/x-shellscript-per-instance'} from ShellScriptByFreqPartHandler: [['text/x-shellscript-per-instance']]
2025-03-13 08:12:38,182 - stages.py[DEBUG]: Added default handler for {'text/x-shellscript-per-once'} from ShellScriptByFreqPartHandler: [['text/x-shellscript-per-once']]
2025-03-13 08:12:38,182 - stages.py[DEBUG]: Added default handler for {'text/cloud-boothook'} from BootHookPartHandler: [['text/cloud-boothook']]
2025-03-13 08:12:38,182 - stages.py[DEBUG]: Added default handler for {'text/jinja2'} from JinjaTemplatePartHandler: [['text/jinja2']]
2025-03-13 08:12:38,185 - handlers[DEBUG]: Calling handler CloudConfigPartHandler: [['text/cloud-config', 'text/cloud-config-jsonp']] (__begin__, None, 3) with frequency once-per-instance
2025-03-13 08:12:38,185 - handlers[DEBUG]: Calling handler ShellScriptPartHandler: [['text/x-shellscript']] (__begin__, None, 2) with frequency once-per-instance
2025-03-13 08:12:38,185 - handlers[DEBUG]: Calling handler ShellScriptByFreqPartHandler: [['text/x-shellscript-per-boot']] (__begin__, None, 2) with frequency once-per-instance
2025-03-13 08:12:38,185 - handlers[DEBUG]: Calling handler ShellScriptByFreqPartHandler: [['text/x-shellscript-per-instance']] (__begin__, None, 2) with frequency once-per-instance
2025-03-13 08:12:38,185 - handlers[DEBUG]: Calling handler ShellScriptByFreqPartHandler: [['text/x-shellscript-per-once']] (__begin__, None, 2) with frequency once-per-instance
2025-03-13 08:12:38,185 - handlers[DEBUG]: Calling handler BootHookPartHandler: [['text/cloud-boothook']] (__begin__, None, 2) with frequency once-per-instance
2025-03-13 08:12:38,185 - handlers[DEBUG]: Calling handler JinjaTemplatePartHandler: [['text/jinja2']] (__begin__, None, 3) with frequency once-per-instance
2025-03-13 08:12:38,185 - handlers[DEBUG]: {'MIME-Version': '1.0', 'Content-Type': 'text/x-not-multipart', 'Content-Disposition': 'attachment; filename="part-001"'}
2025-03-13 08:12:38,185 - handlers[DEBUG]: Empty payload of type text/x-not-multipart
2025-03-13 08:12:38,186 - handlers[DEBUG]: Calling handler CloudConfigPartHandler: [['text/cloud-config', 'text/cloud-config-jsonp']] (__end__, None, 3) with frequency once-per-instance
2025-03-13 08:12:38,186 - util.py[DEBUG]: Writing to /var/lib/cloud/instances/73502904/cloud-config.txt - wb: [600] 0 bytes
2025-03-13 08:12:38,186 - handlers[DEBUG]: Calling handler ShellScriptPartHandler: [['text/x-shellscript']] (__end__, None, 2) with frequency once-per-instance
2025-03-13 08:12:38,186 - handlers[DEBUG]: Calling handler ShellScriptByFreqPartHandler: [['text/x-shellscript-per-boot']] (__end__, None, 2) with frequency once-per-instance
2025-03-13 08:12:38,188 - handlers[DEBUG]: Calling handler ShellScriptByFreqPartHandler: [['text/x-shellscript-per-instance']] (__end__, None, 2) with frequency once-per-instance
2025-03-13 08:12:38,188 - handlers[DEBUG]: Calling handler ShellScriptByFreqPartHandler: [['text/x-shellscript-per-once']] (__end__, None, 2) with frequency once-per-instance
2025-03-13 08:12:38,188 - handlers[DEBUG]: Calling handler BootHookPartHandler: [['text/cloud-boothook']] (__end__, None, 2) with frequency once-per-instance
2025-03-13 08:12:38,188 - handlers[DEBUG]: Calling handler JinjaTemplatePartHandler: [['text/jinja2']] (__end__, None, 3) with frequency once-per-instance
2025-03-13 08:12:38,188 - handlers.py[DEBUG]: finish: init-network/consume-user-data: SUCCESS: reading and applying user-data
2025-03-13 08:12:38,188 - handlers.py[DEBUG]: start: init-network/consume-vendor-data: reading and applying vendor-data
2025-03-13 08:12:38,188 - stages.py[DEBUG]: no vendordata from datasource
2025-03-13 08:12:38,188 - handlers.py[DEBUG]: finish: init-network/consume-vendor-data: SUCCESS: reading and applying vendor-data
2025-03-13 08:12:38,188 - handlers.py[DEBUG]: start: init-network/consume-vendor-data2: reading and applying vendor-data2
2025-03-13 08:12:38,188 - stages.py[DEBUG]: no vendordata2 from datasource
2025-03-13 08:12:38,188 - handlers.py[DEBUG]: finish: init-network/consume-vendor-data2: SUCCESS: reading and applying vendor-data2
2025-03-13 08:12:38,188 - util.py[DEBUG]: Reading from /etc/cloud/cloud.cfg (quiet=False)
2025-03-13 08:12:38,188 - util.py[DEBUG]: Reading 3766 bytes from /etc/cloud/cloud.cfg
2025-03-13 08:12:38,188 - util.py[DEBUG]: Attempting to load yaml from string of length 3766 with allowed root types (<class 'dict'>,)
2025-03-13 08:12:38,205 - util.py[DEBUG]: Reading from /etc/cloud/cloud.cfg.d/99-linode.cfg (quiet=False)
2025-03-13 08:12:38,205 - util.py[DEBUG]: Reading 492 bytes from /etc/cloud/cloud.cfg.d/99-linode.cfg
2025-03-13 08:12:38,205 - util.py[DEBUG]: Attempting to load yaml from string of length 492 with allowed root types (<class 'dict'>,)
2025-03-13 08:12:38,207 - util.py[DEBUG]: Reading from /etc/cloud/cloud.cfg.d/90_dpkg.cfg (quiet=False)
2025-03-13 08:12:38,207 - util.py[DEBUG]: Reading 333 bytes from /etc/cloud/cloud.cfg.d/90_dpkg.cfg
2025-03-13 08:12:38,207 - util.py[DEBUG]: Attempting to load yaml from string of length 333 with allowed root types (<class 'dict'>,)
2025-03-13 08:12:38,209 - util.py[DEBUG]: Reading from /etc/cloud/cloud.cfg.d/05_logging.cfg (quiet=False)
2025-03-13 08:12:38,209 - util.py[DEBUG]: Reading 2071 bytes from /etc/cloud/cloud.cfg.d/05_logging.cfg
2025-03-13 08:12:38,209 - util.py[DEBUG]: Attempting to load yaml from string of length 2071 with allowed root types (<class 'dict'>,)
2025-03-13 08:12:38,213 - util.py[DEBUG]: Reading from /run/cloud-init/cloud.cfg (quiet=False)
2025-03-13 08:12:38,213 - util.py[DEBUG]: Reading 34 bytes from /run/cloud-init/cloud.cfg
2025-03-13 08:12:38,213 - util.py[DEBUG]: Attempting to load yaml from string of length 34 with allowed root types (<class 'dict'>,)
2025-03-13 08:12:38,213 - util.py[DEBUG]: Attempting to load yaml from string of length 0 with allowed root types (<class 'dict'>,)
2025-03-13 08:12:38,213 - util.py[DEBUG]: loaded blob returned None, returning default.
2025-03-13 08:12:38,214 - util.py[DEBUG]: Reading from /var/lib/cloud/instance/cloud-config.txt (quiet=False)
2025-03-13 08:12:38,214 - util.py[DEBUG]: Reading 0 bytes from /var/lib/cloud/instance/cloud-config.txt
2025-03-13 08:12:38,214 - util.py[DEBUG]: Attempting to load yaml from string of length 0 with allowed root types (<class 'dict'>,)
2025-03-13 08:12:38,214 - util.py[DEBUG]: loaded blob returned None, returning default.
2025-03-13 08:12:38,215 - atomic_helper.py[DEBUG]: Atomically writing to file /run/cloud-init/combined-cloud-config.json (via temporary file /run/cloud-init/tmpp5i_nbcc) - w: [600] 5471 bytes/chars
2025-03-13 08:12:38,215 - util.py[DEBUG]: Reading from /run/cloud-init/instance-data-sensitive.json (quiet=False)
2025-03-13 08:12:38,215 - util.py[DEBUG]: Reading 8728 bytes from /run/cloud-init/instance-data-sensitive.json
2025-03-13 08:12:38,216 - atomic_helper.py[DEBUG]: Atomically writing to file /run/cloud-init/instance-data-sensitive.json (via temporary file /run/cloud-init/tmp77k3cw_j) - w: [600] 10711 bytes/chars
2025-03-13 08:12:38,216 - main.py[DEBUG]: Skipping user-data validation. No user-data found.
2025-03-13 08:12:38,216 - util.py[DEBUG]: Reading from /var/lib/cloud/instance/cloud-config.txt (quiet=False)
2025-03-13 08:12:38,217 - util.py[DEBUG]: Reading 0 bytes from /var/lib/cloud/instance/cloud-config.txt
2025-03-13 08:12:38,217 - util.py[DEBUG]: Attempting to load yaml from string of length 0 with allowed root types (<class 'dict'>,)
2025-03-13 08:12:38,217 - util.py[DEBUG]: loaded blob returned None, returning default.
2025-03-13 08:12:38,219 - handlers.py[DEBUG]: start: init-network/activate-datasource: activating datasource
2025-03-13 08:12:38,220 - util.py[DEBUG]: Writing to /var/lib/cloud/instance/obj.pkl - wb: [400] 9372 bytes
2025-03-13 08:12:38,220 - handlers.py[DEBUG]: finish: init-network/activate-datasource: SUCCESS: activating datasource
2025-03-13 08:12:38,220 - main.py[DEBUG]: no di_report found in config.
2025-03-13 08:12:38,231 - stages.py[DEBUG]: Using distro class <class 'cloudinit.distros.ubuntu.Distro'>
2025-03-13 08:12:38,233 - modules.py[INFO]: Skipping modules 'bootcmd,write_files,disk_setup,update_etc_hosts,ca_certs,rsyslog' because no applicable config is provided.
2025-03-13 08:12:38,233 - modules.py[DEBUG]: Running module seed_random (<module 'cloudinit.config.cc_seed_random' from '/usr/lib/python3/dist-packages/cloudinit/config/cc_seed_random.py'>) with frequency once-per-instance
2025-03-13 08:12:38,234 - handlers.py[DEBUG]: start: init-network/config-seed_random: running config-seed_random with frequency once-per-instance
2025-03-13 08:12:38,234 - util.py[DEBUG]: Writing to /var/lib/cloud/instances/73502904/sem/config_seed_random - wb: [644] 24 bytes
2025-03-13 08:12:38,234 - helpers.py[DEBUG]: Running config-seed_random using lock (<FileLock using file '/var/lib/cloud/instances/73502904/sem/config_seed_random'>)
2025-03-13 08:12:38,234 - cc_seed_random.py[DEBUG]: no command provided
2025-03-13 08:12:38,234 - handlers.py[DEBUG]: finish: init-network/config-seed_random: SUCCESS: config-seed_random ran successfully and took 0.001 seconds
2025-03-13 08:12:38,234 - modules.py[DEBUG]: Running module growpart (<module 'cloudinit.config.cc_growpart' from '/usr/lib/python3/dist-packages/cloudinit/config/cc_growpart.py'>) with frequency always
2025-03-13 08:12:38,234 - handlers.py[DEBUG]: start: init-network/config-growpart: running config-growpart with frequency always
2025-03-13 08:12:38,235 - helpers.py[DEBUG]: Running config-growpart using lock (<cloudinit.helpers.DummyLock object at 0x7fabd33bd5d0>)
2025-03-13 08:12:38,235 - cc_growpart.py[DEBUG]: No 'growpart' entry in cfg.  Using default: {'mode': 'auto', 'devices': ['/'], 'ignore_growroot_disabled': False}
2025-03-13 08:12:38,235 - subp.py[DEBUG]: Running command ['growpart', '--help'] with allowed return codes [0] (shell=False, capture=True)
2025-03-13 08:12:38,237 - util.py[DEBUG]: Reading from /proc/566/mountinfo (quiet=False)
2025-03-13 08:12:38,238 - util.py[DEBUG]: Reading 2056 bytes from /proc/566/mountinfo
2025-03-13 08:12:38,238 - cc_growpart.py[DEBUG]: growpart found fs=ext4
2025-03-13 08:12:38,238 - cc_growpart.py[DEBUG]: '/' SKIPPED: device_part_info(/dev/sda) failed: /dev/sda not a partition
2025-03-13 08:12:38,238 - handlers.py[DEBUG]: finish: init-network/config-growpart: SUCCESS: config-growpart ran successfully and took 0.003 seconds
2025-03-13 08:12:38,238 - modules.py[DEBUG]: Running module resizefs (<module 'cloudinit.config.cc_resizefs' from '/usr/lib/python3/dist-packages/cloudinit/config/cc_resizefs.py'>) with frequency always
2025-03-13 08:12:38,238 - handlers.py[DEBUG]: start: init-network/config-resizefs: running config-resizefs with frequency always
2025-03-13 08:12:38,238 - helpers.py[DEBUG]: Running config-resizefs using lock (<cloudinit.helpers.DummyLock object at 0x7fabd33bc9a0>)
2025-03-13 08:12:38,238 - util.py[DEBUG]: Reading from /proc/566/mountinfo (quiet=False)
2025-03-13 08:12:38,239 - util.py[DEBUG]: Reading 2056 bytes from /proc/566/mountinfo
2025-03-13 08:12:38,239 - cc_resizefs.py[DEBUG]: resize_info: dev=/dev/sda mnt_point=/ path=/
2025-03-13 08:12:38,239 - cc_resizefs.py[DEBUG]: Resizing / (ext4) using resize2fs /dev/sda
2025-03-13 08:12:38,239 - subp.py[DEBUG]: Running command ('resize2fs', '/dev/sda') with allowed return codes [0] (shell=False, capture=True)
2025-03-13 08:12:38,253 - performance.py[DEBUG]: Running ('resize2fs', '/dev/sda') took 0.014 seconds
2025-03-13 08:12:38,253 - cc_resizefs.py[DEBUG]: Resized root filesystem (type=ext4, val=True)
2025-03-13 08:12:38,253 - handlers.py[DEBUG]: finish: init-network/config-resizefs: SUCCESS: config-resizefs ran successfully and took 0.015 seconds
2025-03-13 08:12:38,253 - modules.py[DEBUG]: Running module mounts (<module 'cloudinit.config.cc_mounts' from '/usr/lib/python3/dist-packages/cloudinit/config/cc_mounts.py'>) with frequency once-per-instance
2025-03-13 08:12:38,253 - handlers.py[DEBUG]: start: init-network/config-mounts: running config-mounts with frequency once-per-instance
2025-03-13 08:12:38,253 - util.py[DEBUG]: Writing to /var/lib/cloud/instances/73502904/sem/config_mounts - wb: [644] 23 bytes
2025-03-13 08:12:38,254 - helpers.py[DEBUG]: Running config-mounts using lock (<FileLock using file '/var/lib/cloud/instances/73502904/sem/config_mounts'>)
2025-03-13 08:12:38,254 - cc_mounts.py[DEBUG]: mounts configuration is []
2025-03-13 08:12:38,254 - util.py[DEBUG]: Reading from /etc/fstab (quiet=False)
2025-03-13 08:12:38,255 - util.py[DEBUG]: Reading 481 bytes from /etc/fstab
2025-03-13 08:12:38,255 - cc_mounts.py[DEBUG]: Attempting to determine the real name of ephemeral0
2025-03-13 08:12:38,255 - cc_mounts.py[DEBUG]: changed ephemeral0 => None
2025-03-13 08:12:38,255 - cc_mounts.py[DEBUG]: Ignoring nonexistent default named mount ephemeral0
2025-03-13 08:12:38,255 - cc_mounts.py[DEBUG]: Attempting to determine the real name of swap
2025-03-13 08:12:38,255 - cc_mounts.py[DEBUG]: changed swap => None
2025-03-13 08:12:38,255 - cc_mounts.py[DEBUG]: Ignoring nonexistent default named mount swap
2025-03-13 08:12:38,255 - cc_mounts.py[DEBUG]: no need to setup swap
2025-03-13 08:12:38,256 - cc_mounts.py[DEBUG]: No modifications to fstab needed
2025-03-13 08:12:38,256 - handlers.py[DEBUG]: finish: init-network/config-mounts: SUCCESS: config-mounts ran successfully and took 0.002 seconds
2025-03-13 08:12:38,256 - modules.py[DEBUG]: Running module set_hostname (<module 'cloudinit.config.cc_set_hostname' from '/usr/lib/python3/dist-packages/cloudinit/config/cc_set_hostname.py'>) with frequency once-per-instance
2025-03-13 08:12:38,256 - handlers.py[DEBUG]: start: init-network/config-set_hostname: running config-set_hostname with frequency once-per-instance
2025-03-13 08:12:38,256 - util.py[DEBUG]: Writing to /var/lib/cloud/instances/73502904/sem/config_set_hostname - wb: [644] 24 bytes
2025-03-13 08:12:38,256 - helpers.py[DEBUG]: Running config-set_hostname using lock (<FileLock using file '/var/lib/cloud/instances/73502904/sem/config_set_hostname'>)
2025-03-13 08:12:38,257 - util.py[DEBUG]: Reading from /etc/hosts (quiet=False)
2025-03-13 08:12:38,257 - util.py[DEBUG]: Reading 181 bytes from /etc/hosts
2025-03-13 08:12:38,257 - util.py[DEBUG]: Reading from /etc/hosts (quiet=False)
2025-03-13 08:12:38,257 - util.py[DEBUG]: Reading 181 bytes from /etc/hosts
2025-03-13 08:12:38,257 - cc_set_hostname.py[DEBUG]: Hostname is localhost. Let other services handle this.
2025-03-13 08:12:38,257 - handlers.py[DEBUG]: finish: init-network/config-set_hostname: SUCCESS: config-set_hostname ran successfully and took 0.001 seconds
2025-03-13 08:12:38,257 - modules.py[DEBUG]: Running module update_hostname (<module 'cloudinit.config.cc_update_hostname' from '/usr/lib/python3/dist-packages/cloudinit/config/cc_update_hostname.py'>) with frequency always
2025-03-13 08:12:38,257 - handlers.py[DEBUG]: start: init-network/config-update_hostname: running config-update_hostname with frequency always
2025-03-13 08:12:38,257 - helpers.py[DEBUG]: Running config-update_hostname using lock (<cloudinit.helpers.DummyLock object at 0x7fabd33bc160>)
2025-03-13 08:12:38,257 - util.py[DEBUG]: Reading from /etc/hosts (quiet=False)
2025-03-13 08:12:38,257 - util.py[DEBUG]: Reading 181 bytes from /etc/hosts
2025-03-13 08:12:38,257 - util.py[DEBUG]: Reading from /etc/hosts (quiet=False)
2025-03-13 08:12:38,257 - util.py[DEBUG]: Reading 181 bytes from /etc/hosts
2025-03-13 08:12:38,257 - cc_update_hostname.py[DEBUG]: Hostname is localhost. Let other services handle this.
2025-03-13 08:12:38,258 - handlers.py[DEBUG]: finish: init-network/config-update_hostname: SUCCESS: config-update_hostname ran successfully and took 0.000 seconds
2025-03-13 08:12:38,258 - modules.py[DEBUG]: Running module users_groups (<module 'cloudinit.config.cc_users_groups' from '/usr/lib/python3/dist-packages/cloudinit/config/cc_users_groups.py'>) with frequency once-per-instance
2025-03-13 08:12:38,258 - handlers.py[DEBUG]: start: init-network/config-users_groups: running config-users_groups with frequency once-per-instance
2025-03-13 08:12:38,258 - util.py[DEBUG]: Writing to /var/lib/cloud/instances/73502904/sem/config_users_groups - wb: [644] 24 bytes
2025-03-13 08:12:38,261 - helpers.py[DEBUG]: Running config-users_groups using lock (<FileLock using file '/var/lib/cloud/instances/73502904/sem/config_users_groups'>)
2025-03-13 08:12:38,261 - handlers.py[DEBUG]: finish: init-network/config-users_groups: SUCCESS: config-users_groups ran successfully and took 0.003 seconds
2025-03-13 08:12:38,261 - modules.py[DEBUG]: Running module ssh (<module 'cloudinit.config.cc_ssh' from '/usr/lib/python3/dist-packages/cloudinit/config/cc_ssh.py'>) with frequency once-per-instance
2025-03-13 08:12:38,261 - handlers.py[DEBUG]: start: init-network/config-ssh: running config-ssh with frequency once-per-instance
2025-03-13 08:12:38,262 - util.py[DEBUG]: Writing to /var/lib/cloud/instances/73502904/sem/config_ssh - wb: [644] 24 bytes
2025-03-13 08:12:38,262 - helpers.py[DEBUG]: Running config-ssh using lock (<FileLock using file '/var/lib/cloud/instances/73502904/sem/config_ssh'>)
2025-03-13 08:12:38,264 - util.py[DEBUG]: Reading from /proc/sys/crypto/fips_enabled (quiet=False)
2025-03-13 08:12:38,264 - subp.py[DEBUG]: Running command ['ssh-keygen', '-t', 'rsa', '-N', '', '-f', '/etc/ssh/ssh_host_rsa_key'] with allowed return codes [0] (shell=False, capture=True)
2025-03-13 08:12:38,795 - performance.py[DEBUG]: Running ['ssh-keygen', '-t', 'rsa', '-N', '', '-f', '/etc/ssh/ssh_host_rsa_key'] took 0.531 seconds
2025-03-13 08:12:38,795 - subp.py[DEBUG]: Running command ['ssh-keygen', '-t', 'ecdsa', '-N', '', '-f', '/etc/ssh/ssh_host_ecdsa_key'] with allowed return codes [0] (shell=False, capture=True)
2025-03-13 08:12:38,800 - subp.py[DEBUG]: Running command ['ssh-keygen', '-t', 'ed25519', '-N', '', '-f', '/etc/ssh/ssh_host_ed25519_key'] with allowed return codes [0] (shell=False, capture=True)
2025-03-13 08:12:38,807 - util.py[DEBUG]: Reading from /etc/ssh/ssh_host_rsa_key.pub (quiet=False)
2025-03-13 08:12:38,807 - util.py[DEBUG]: Reading 568 bytes from /etc/ssh/ssh_host_rsa_key.pub
2025-03-13 08:12:38,807 - util.py[DEBUG]: Reading from /etc/ssh/ssh_host_ed25519_key.pub (quiet=False)
2025-03-13 08:12:38,807 - util.py[DEBUG]: Reading 96 bytes from /etc/ssh/ssh_host_ed25519_key.pub
2025-03-13 08:12:38,807 - util.py[DEBUG]: Reading from /etc/ssh/ssh_host_ecdsa_key.pub (quiet=False)
2025-03-13 08:12:38,807 - util.py[DEBUG]: Reading 176 bytes from /etc/ssh/ssh_host_ecdsa_key.pub
2025-03-13 08:12:38,808 - util.py[DEBUG]: Reading from /etc/ssh/sshd_config (quiet=False)
2025-03-13 08:12:38,808 - util.py[DEBUG]: Reading 3237 bytes from /etc/ssh/sshd_config
2025-03-13 08:12:38,809 - util.py[DEBUG]: Reading from /root/.ssh/authorized_keys (quiet=False)
2025-03-13 08:12:38,809 - util.py[DEBUG]: Reading 1486 bytes from /root/.ssh/authorized_keys
2025-03-13 08:12:38,809 - util.py[DEBUG]: Writing to /root/.ssh/authorized_keys - wb: [600] 1487 bytes
2025-03-13 08:12:38,810 - handlers.py[DEBUG]: finish: init-network/config-ssh: SUCCESS: config-ssh ran successfully and took 0.548 seconds
2025-03-13 08:12:38,810 - modules.py[DEBUG]: Running module set_passwords (<module 'cloudinit.config.cc_set_passwords' from '/usr/lib/python3/dist-packages/cloudinit/config/cc_set_passwords.py'>) with frequency once-per-instance
2025-03-13 08:12:38,810 - handlers.py[DEBUG]: start: init-network/config-set_passwords: running config-set_passwords with frequency once-per-instance
2025-03-13 08:12:38,810 - util.py[DEBUG]: Writing to /var/lib/cloud/instances/73502904/sem/config_set_passwords - wb: [644] 24 bytes
2025-03-13 08:12:38,811 - helpers.py[DEBUG]: Running config-set_passwords using lock (<FileLock using file '/var/lib/cloud/instances/73502904/sem/config_set_passwords'>)
2025-03-13 08:12:38,811 - cc_set_passwords.py[DEBUG]: Leaving SSH config 'PasswordAuthentication' unchanged. ssh_pwauth=None
2025-03-13 08:12:38,811 - handlers.py[DEBUG]: finish: init-network/config-set_passwords: SUCCESS: config-set_passwords ran successfully and took 0.001 seconds
2025-03-13 08:12:38,811 - main.py[DEBUG]: Ran 9 modules with 0 failures
2025-03-13 08:12:38,811 - util.py[DEBUG]: Reading from /proc/uptime (quiet=False)
2025-03-13 08:12:38,811 - util.py[DEBUG]: Reading 11 bytes from /proc/uptime
2025-03-13 08:12:38,811 - atomic_helper.py[DEBUG]: Atomically writing to file /var/lib/cloud/data/status.json (via temporary file /var/lib/cloud/data/tmpulvkskh9) - w: [644] 504 bytes/chars
2025-03-13 08:12:38,811 - performance.py[DEBUG]: cloud-init stage: 'init-network' took 0.777 seconds
2025-03-13 08:12:38,811 - handlers.py[DEBUG]: finish: init-network: SUCCESS: searching for network datasources
2025-03-13 08:12:40,022 - log_util.py[DEBUG]: Cloud-init v. 24.4-0ubuntu1~22.04.1 running 'modules:config' at Thu, 13 Mar 2025 08:12:39 +0000. Up 17.07 seconds.
2025-03-13 08:12:40,022 - main.py[INFO]: PID [1] started cloud-init 'modules:config'.
2025-03-13 08:12:40,044 - stages.py[DEBUG]: Using distro class <class 'cloudinit.distros.ubuntu.Distro'>
2025-03-13 08:12:40,045 - modules.py[INFO]: Skipping modules 'wireguard,snap,ubuntu_autoinstall,keyboard,apt_pipelining,ubuntu_pro,ntp,timezone,disable_ec2_metadata,runcmd' because no applicable config is provided.
2025-03-13 08:12:40,046 - modules.py[DEBUG]: Running module ssh_import_id (<module 'cloudinit.config.cc_ssh_import_id' from '/usr/lib/python3/dist-packages/cloudinit/config/cc_ssh_import_id.py'>) with frequency once-per-instance
2025-03-13 08:12:40,046 - handlers.py[DEBUG]: start: modules-config/config-ssh_import_id: running config-ssh_import_id with frequency once-per-instance
2025-03-13 08:12:40,048 - util.py[DEBUG]: Writing to /var/lib/cloud/instances/73502904/sem/config_ssh_import_id - wb: [644] 24 bytes
2025-03-13 08:12:40,049 - helpers.py[DEBUG]: Running config-ssh_import_id using lock (<FileLock using file '/var/lib/cloud/instances/73502904/sem/config_ssh_import_id'>)
2025-03-13 08:12:40,049 - cc_ssh_import_id.py[DEBUG]: Skipping module named ssh_import_id, no 'ssh_import_id' directives found.
2025-03-13 08:12:40,049 - handlers.py[DEBUG]: finish: modules-config/config-ssh_import_id: SUCCESS: config-ssh_import_id ran successfully and took 0.003 seconds
2025-03-13 08:12:40,049 - modules.py[DEBUG]: Running module locale (<module 'cloudinit.config.cc_locale' from '/usr/lib/python3/dist-packages/cloudinit/config/cc_locale.py'>) with frequency once-per-instance
2025-03-13 08:12:40,049 - handlers.py[DEBUG]: start: modules-config/config-locale: running config-locale with frequency once-per-instance
2025-03-13 08:12:40,049 - util.py[DEBUG]: Writing to /var/lib/cloud/instances/73502904/sem/config_locale - wb: [644] 24 bytes
2025-03-13 08:12:40,049 - helpers.py[DEBUG]: Running config-locale using lock (<FileLock using file '/var/lib/cloud/instances/73502904/sem/config_locale'>)
2025-03-13 08:12:40,049 - util.py[DEBUG]: Reading from /etc/default/locale (quiet=False)
2025-03-13 08:12:40,049 - util.py[DEBUG]: Reading 52 bytes from /etc/default/locale
2025-03-13 08:12:40,050 - cc_locale.py[DEBUG]: Setting locale to en_US.UTF-8
2025-03-13 08:12:40,050 - debian.py[DEBUG]: System locale set to en_US.UTF-8 via /etc/default/locale
2025-03-13 08:12:40,050 - debian.py[DEBUG]: System has 'LANG=en_US.UTF-8' requested 'en_US.UTF-8', skipping regeneration.
2025-03-13 08:12:40,050 - handlers.py[DEBUG]: finish: modules-config/config-locale: SUCCESS: config-locale ran successfully and took 0.001 seconds
2025-03-13 08:12:40,050 - modules.py[DEBUG]: Running module grub_dpkg (<module 'cloudinit.config.cc_grub_dpkg' from '/usr/lib/python3/dist-packages/cloudinit/config/cc_grub_dpkg.py'>) with frequency once-per-instance
2025-03-13 08:12:40,050 - handlers.py[DEBUG]: start: modules-config/config-grub_dpkg: running config-grub_dpkg with frequency once-per-instance
2025-03-13 08:12:40,050 - util.py[DEBUG]: Writing to /var/lib/cloud/instances/73502904/sem/config_grub_dpkg - wb: [644] 24 bytes
2025-03-13 08:12:40,054 - helpers.py[DEBUG]: Running config-grub_dpkg using lock (<FileLock using file '/var/lib/cloud/instances/73502904/sem/config_grub_dpkg'>)
2025-03-13 08:12:40,054 - subp.py[DEBUG]: Running command ['grub-probe', '-t', 'disk', '/boot'] with allowed return codes [0] (shell=False, capture=True)
2025-03-13 08:12:40,064 - subp.py[DEBUG]: Running command ['udevadm', 'info', '--root', '--query=symlink', '/dev/sda'] with allowed return codes [0] (shell=False, capture=True)
2025-03-13 08:12:40,069 - cc_grub_dpkg.py[DEBUG]: considering these device symlinks: /dev/disk/by-id/scsi-0QEMU_QEMU_HARDDISK_drive-scsi-disk-0,/dev/disk/by-label/linode-root,/dev/disk/by-path/pci-0000:00:02.0-scsi-0:0:0:0,/dev/disk/by-uuid/c4b52a3f-818a-c891-ac4a-b949bf511e72
2025-03-13 08:12:40,069 - cc_grub_dpkg.py[DEBUG]: filtered to these disk/by-id symlinks: /dev/disk/by-id/scsi-0QEMU_QEMU_HARDDISK_drive-scsi-disk-0
2025-03-13 08:12:40,069 - cc_grub_dpkg.py[DEBUG]: selected /dev/disk/by-id/scsi-0QEMU_QEMU_HARDDISK_drive-scsi-disk-0
2025-03-13 08:12:40,069 - cc_grub_dpkg.py[DEBUG]: Setting grub debconf-set-selections with 'grub-pc grub-pc/install_devices string /dev/disk/by-id/scsi-0QEMU_QEMU_HARDDISK_drive-scsi-disk-0
grub-pc grub-pc/install_devices_empty boolean false
'
2025-03-13 08:12:40,069 - subp.py[DEBUG]: Running command ['debconf-set-selections'] with allowed return codes [0] (shell=False, capture=True)
2025-03-13 08:12:40,235 - performance.py[DEBUG]: Running ['debconf-set-selections'] took 0.166 seconds
2025-03-13 08:12:40,235 - handlers.py[DEBUG]: finish: modules-config/config-grub_dpkg: SUCCESS: config-grub_dpkg ran successfully and took 0.185 seconds
2025-03-13 08:12:40,235 - modules.py[DEBUG]: Running module apt_configure (<module 'cloudinit.config.cc_apt_configure' from '/usr/lib/python3/dist-packages/cloudinit/config/cc_apt_configure.py'>) with frequency once-per-instance
2025-03-13 08:12:40,235 - handlers.py[DEBUG]: start: modules-config/config-apt_configure: running config-apt_configure with frequency once-per-instance
2025-03-13 08:12:40,236 - util.py[DEBUG]: Writing to /var/lib/cloud/instances/73502904/sem/config_apt_configure - wb: [644] 24 bytes
2025-03-13 08:12:40,236 - helpers.py[DEBUG]: Running config-apt_configure using lock (<FileLock using file '/var/lib/cloud/instances/73502904/sem/config_apt_configure'>)
2025-03-13 08:12:40,236 - cc_apt_configure.py[DEBUG]: debconf_selections was not set in config
2025-03-13 08:12:40,237 - cc_apt_configure.py[DEBUG]: handling apt config: {'preserve_sources_list': True}
2025-03-13 08:12:40,237 - subp.py[DEBUG]: Running command ['lsb_release', '--all'] with allowed return codes [0] (shell=False, capture=True)
2025-03-13 08:12:40,281 - performance.py[DEBUG]: Running ['lsb_release', '--all'] took 0.044 seconds
2025-03-13 08:12:40,281 - subp.py[DEBUG]: Running command ['dpkg', '--print-architecture'] with allowed return codes [0] (shell=False, capture=True)
2025-03-13 08:12:40,284 - cc_apt_configure.py[DEBUG]: got primary mirror: None
2025-03-13 08:12:40,284 - cc_apt_configure.py[DEBUG]: got security mirror: None
2025-03-13 08:12:40,285 - util.py[DEBUG]: search for mirror in candidates: '['http://es-mad.clouds.archive.ubuntu.com/ubuntu/']'
2025-03-13 08:12:40,625 - performance.py[DEBUG]: Resolving URL took 0.341 seconds
2025-03-13 08:12:40,626 - util.py[DEBUG]: found working mirror: 'http://es-mad.clouds.archive.ubuntu.com/ubuntu/'
2025-03-13 08:12:40,626 - util.py[DEBUG]: search for mirror in candidates: '[]'
2025-03-13 08:12:40,626 - distros[DEBUG]: filtered distro mirror info: {'primary': 'http://es-mad.clouds.archive.ubuntu.com/ubuntu/', 'security': 'http://security.ubuntu.com/ubuntu'}
2025-03-13 08:12:40,626 - cc_apt_configure.py[DEBUG]: Apt Mirror info: {'primary': 'http://es-mad.clouds.archive.ubuntu.com/ubuntu/', 'security': 'http://security.ubuntu.com/ubuntu', 'PRIMARY': 'http://es-mad.clouds.archive.ubuntu.com/ubuntu/', 'SECURITY': 'http://security.ubuntu.com/ubuntu', 'MIRROR': 'http://es-mad.clouds.archive.ubuntu.com/ubuntu/'}
2025-03-13 08:12:40,626 - handlers.py[DEBUG]: finish: modules-config/config-apt_configure: SUCCESS: config-apt_configure ran successfully and took 0.391 seconds
2025-03-13 08:12:40,626 - modules.py[DEBUG]: Running module byobu (<module 'cloudinit.config.cc_byobu' from '/usr/lib/python3/dist-packages/cloudinit/config/cc_byobu.py'>) with frequency once-per-instance
2025-03-13 08:12:40,626 - handlers.py[DEBUG]: start: modules-config/config-byobu: running config-byobu with frequency once-per-instance
2025-03-13 08:12:40,627 - util.py[DEBUG]: Writing to /var/lib/cloud/instances/73502904/sem/config_byobu - wb: [644] 23 bytes
2025-03-13 08:12:40,627 - helpers.py[DEBUG]: Running config-byobu using lock (<FileLock using file '/var/lib/cloud/instances/73502904/sem/config_byobu'>)
2025-03-13 08:12:40,627 - cc_byobu.py[DEBUG]: Skipping module named byobu, no 'byobu' values found
2025-03-13 08:12:40,627 - handlers.py[DEBUG]: finish: modules-config/config-byobu: SUCCESS: config-byobu ran successfully and took 0.000 seconds
2025-03-13 08:12:40,627 - main.py[DEBUG]: Ran 5 modules with 0 failures
2025-03-13 08:12:40,627 - util.py[DEBUG]: Reading from /proc/uptime (quiet=False)
2025-03-13 08:12:40,627 - util.py[DEBUG]: Reading 11 bytes from /proc/uptime
2025-03-13 08:12:40,628 - atomic_helper.py[DEBUG]: Atomically writing to file /var/lib/cloud/data/status.json (via temporary file /var/lib/cloud/data/tmpoq7s3qqz) - w: [644] 506 bytes/chars
2025-03-13 08:12:40,628 - performance.py[DEBUG]: cloud-init stage: 'modules-config' took 0.805 seconds
2025-03-13 08:12:40,628 - handlers.py[DEBUG]: finish: modules-config: SUCCESS: running modules for config
2025-03-13 08:12:40,977 - log_util.py[DEBUG]: Cloud-init v. 24.4-0ubuntu1~22.04.1 running 'modules:final' at Thu, 13 Mar 2025 08:12:40 +0000. Up 18.12 seconds.
2025-03-13 08:12:40,977 - main.py[INFO]: PID [1] started cloud-init 'modules:final'.
2025-03-13 08:12:40,996 - stages.py[DEBUG]: Using distro class <class 'cloudinit.distros.ubuntu.Distro'>
2025-03-13 08:12:40,999 - modules.py[INFO]: Skipping modules 'package_update_upgrade_install,fan,landscape,lxd,ubuntu_drivers,write_files_deferred,puppet,chef,ansible,mcollective,salt_minion,phone_home,power_state_change' because no applicable config is provided.
2025-03-13 08:12:40,999 - modules.py[DEBUG]: Running module reset_rmc (<module 'cloudinit.config.cc_reset_rmc' from '/usr/lib/python3/dist-packages/cloudinit/config/cc_reset_rmc.py'>) with frequency once-per-instance
2025-03-13 08:12:40,999 - handlers.py[DEBUG]: start: modules-final/config-reset_rmc: running config-reset_rmc with frequency once-per-instance
2025-03-13 08:12:41,000 - util.py[DEBUG]: Writing to /var/lib/cloud/instances/73502904/sem/config_reset_rmc - wb: [644] 24 bytes
2025-03-13 08:12:41,000 - helpers.py[DEBUG]: Running config-reset_rmc using lock (<FileLock using file '/var/lib/cloud/instances/73502904/sem/config_reset_rmc'>)
2025-03-13 08:12:41,000 - cc_reset_rmc.py[DEBUG]: module disabled, RSCT_PATH not present
2025-03-13 08:12:41,000 - handlers.py[DEBUG]: finish: modules-final/config-reset_rmc: SUCCESS: config-reset_rmc ran successfully and took 0.001 seconds
2025-03-13 08:12:41,000 - modules.py[DEBUG]: Running module scripts_vendor (<module 'cloudinit.config.cc_scripts_vendor' from '/usr/lib/python3/dist-packages/cloudinit/config/cc_scripts_vendor.py'>) with frequency once-per-instance
2025-03-13 08:12:41,000 - handlers.py[DEBUG]: start: modules-final/config-scripts_vendor: running config-scripts_vendor with frequency once-per-instance
2025-03-13 08:12:41,001 - util.py[DEBUG]: Writing to /var/lib/cloud/instances/73502904/sem/config_scripts_vendor - wb: [644] 24 bytes
2025-03-13 08:12:41,001 - helpers.py[DEBUG]: Running config-scripts_vendor using lock (<FileLock using file '/var/lib/cloud/instances/73502904/sem/config_scripts_vendor'>)
2025-03-13 08:12:41,001 - handlers.py[DEBUG]: finish: modules-final/config-scripts_vendor: SUCCESS: config-scripts_vendor ran successfully and took 0.000 seconds
2025-03-13 08:12:41,001 - modules.py[DEBUG]: Running module scripts_per_once (<module 'cloudinit.config.cc_scripts_per_once' from '/usr/lib/python3/dist-packages/cloudinit/config/cc_scripts_per_once.py'>) with frequency once
2025-03-13 08:12:41,001 - handlers.py[DEBUG]: start: modules-final/config-scripts_per_once: running config-scripts_per_once with frequency once
2025-03-13 08:12:41,001 - util.py[DEBUG]: Writing to /var/lib/cloud/sem/config_scripts_per_once.once - wb: [644] 24 bytes
2025-03-13 08:12:41,002 - helpers.py[DEBUG]: Running config-scripts_per_once using lock (<FileLock using file '/var/lib/cloud/sem/config_scripts_per_once.once'>)
2025-03-13 08:12:41,002 - handlers.py[DEBUG]: finish: modules-final/config-scripts_per_once: SUCCESS: config-scripts_per_once ran successfully and took 0.000 seconds
2025-03-13 08:12:41,002 - modules.py[DEBUG]: Running module scripts_per_boot (<module 'cloudinit.config.cc_scripts_per_boot' from '/usr/lib/python3/dist-packages/cloudinit/config/cc_scripts_per_boot.py'>) with frequency always
2025-03-13 08:12:41,002 - handlers.py[DEBUG]: start: modules-final/config-scripts_per_boot: running config-scripts_per_boot with frequency always
2025-03-13 08:12:41,002 - helpers.py[DEBUG]: Running config-scripts_per_boot using lock (<cloudinit.helpers.DummyLock object at 0x7fbaae1ab6d0>)
2025-03-13 08:12:41,002 - handlers.py[DEBUG]: finish: modules-final/config-scripts_per_boot: SUCCESS: config-scripts_per_boot ran successfully and took 0.000 seconds
2025-03-13 08:12:41,002 - modules.py[DEBUG]: Running module scripts_per_instance (<module 'cloudinit.config.cc_scripts_per_instance' from '/usr/lib/python3/dist-packages/cloudinit/config/cc_scripts_per_instance.py'>) with frequency once-per-instance
2025-03-13 08:12:41,003 - handlers.py[DEBUG]: start: modules-final/config-scripts_per_instance: running config-scripts_per_instance with frequency once-per-instance
2025-03-13 08:12:41,003 - util.py[DEBUG]: Writing to /var/lib/cloud/instances/73502904/sem/config_scripts_per_instance - wb: [644] 24 bytes
2025-03-13 08:12:41,003 - helpers.py[DEBUG]: Running config-scripts_per_instance using lock (<FileLock using file '/var/lib/cloud/instances/73502904/sem/config_scripts_per_instance'>)
2025-03-13 08:12:41,003 - handlers.py[DEBUG]: finish: modules-final/config-scripts_per_instance: SUCCESS: config-scripts_per_instance ran successfully and took 0.000 seconds
2025-03-13 08:12:41,003 - modules.py[DEBUG]: Running module scripts_user (<module 'cloudinit.config.cc_scripts_user' from '/usr/lib/python3/dist-packages/cloudinit/config/cc_scripts_user.py'>) with frequency once-per-instance
2025-03-13 08:12:41,003 - handlers.py[DEBUG]: start: modules-final/config-scripts_user: running config-scripts_user with frequency once-per-instance
2025-03-13 08:12:41,003 - util.py[DEBUG]: Writing to /var/lib/cloud/instances/73502904/sem/config_scripts_user - wb: [644] 24 bytes
2025-03-13 08:12:41,004 - helpers.py[DEBUG]: Running config-scripts_user using lock (<FileLock using file '/var/lib/cloud/instances/73502904/sem/config_scripts_user'>)
2025-03-13 08:12:41,004 - handlers.py[DEBUG]: finish: modules-final/config-scripts_user: SUCCESS: config-scripts_user ran successfully and took 0.001 seconds
2025-03-13 08:12:41,004 - modules.py[DEBUG]: Running module ssh_authkey_fingerprints (<module 'cloudinit.config.cc_ssh_authkey_fingerprints' from '/usr/lib/python3/dist-packages/cloudinit/config/cc_ssh_authkey_fingerprints.py'>) with frequency once-per-instance
2025-03-13 08:12:41,004 - handlers.py[DEBUG]: start: modules-final/config-ssh_authkey_fingerprints: running config-ssh_authkey_fingerprints with frequency once-per-instance
2025-03-13 08:12:41,004 - util.py[DEBUG]: Writing to /var/lib/cloud/instances/73502904/sem/config_ssh_authkey_fingerprints - wb: [644] 23 bytes
2025-03-13 08:12:41,005 - helpers.py[DEBUG]: Running config-ssh_authkey_fingerprints using lock (<FileLock using file '/var/lib/cloud/instances/73502904/sem/config_ssh_authkey_fingerprints'>)
2025-03-13 08:12:41,005 - handlers.py[DEBUG]: finish: modules-final/config-ssh_authkey_fingerprints: SUCCESS: config-ssh_authkey_fingerprints ran successfully and took 0.000 seconds
2025-03-13 08:12:41,005 - modules.py[DEBUG]: Running module keys_to_console (<module 'cloudinit.config.cc_keys_to_console' from '/usr/lib/python3/dist-packages/cloudinit/config/cc_keys_to_console.py'>) with frequency once-per-instance
2025-03-13 08:12:41,005 - handlers.py[DEBUG]: start: modules-final/config-keys_to_console: running config-keys_to_console with frequency once-per-instance
2025-03-13 08:12:41,005 - util.py[DEBUG]: Writing to /var/lib/cloud/instances/73502904/sem/config_keys_to_console - wb: [644] 24 bytes
2025-03-13 08:12:41,005 - helpers.py[DEBUG]: Running config-keys_to_console using lock (<FileLock using file '/var/lib/cloud/instances/73502904/sem/config_keys_to_console'>)
2025-03-13 08:12:41,006 - subp.py[DEBUG]: Running command ['/usr/lib/cloud-init/write-ssh-key-fingerprints', '', ''] with allowed return codes [0] (shell=False, capture=True)
2025-03-13 08:12:41,033 - performance.py[DEBUG]: Running ['/usr/lib/cloud-init/write-ssh-key-fingerprints', '', ''] took 0.028 seconds
2025-03-13 08:12:41,054 - performance.py[DEBUG]: Writing to console took 0.020 seconds
2025-03-13 08:12:41,054 - handlers.py[DEBUG]: finish: modules-final/config-keys_to_console: SUCCESS: config-keys_to_console ran successfully and took 0.049 seconds
2025-03-13 08:12:41,054 - modules.py[DEBUG]: Running module install_hotplug (<module 'cloudinit.config.cc_install_hotplug' from '/usr/lib/python3/dist-packages/cloudinit/config/cc_install_hotplug.py'>) with frequency once-per-instance
2025-03-13 08:12:41,054 - handlers.py[DEBUG]: start: modules-final/config-install_hotplug: running config-install_hotplug with frequency once-per-instance
2025-03-13 08:12:41,054 - util.py[DEBUG]: Writing to /var/lib/cloud/instances/73502904/sem/config_install_hotplug - wb: [644] 24 bytes
2025-03-13 08:12:41,055 - helpers.py[DEBUG]: Running config-install_hotplug using lock (<FileLock using file '/var/lib/cloud/instances/73502904/sem/config_install_hotplug'>)
2025-03-13 08:12:41,055 - util.py[DEBUG]: Reading from /var/lib/cloud/hotplug.enabled (quiet=False)
2025-03-13 08:12:41,055 - util.py[DEBUG]: File not found: /var/lib/cloud/hotplug.enabled
2025-03-13 08:12:41,055 - stages.py[DEBUG]: Allowed events: {<EventScope.NETWORK: 'network'>: {<EventType.BOOT_NEW_INSTANCE: 'boot-new-instance'>}}
2025-03-13 08:12:41,055 - stages.py[DEBUG]: Event Denied: scopes=['network'] EventType=hotplug
2025-03-13 08:12:41,055 - cc_install_hotplug.py[DEBUG]: Skipping hotplug install, not enabled
2025-03-13 08:12:41,055 - handlers.py[DEBUG]: finish: modules-final/config-install_hotplug: SUCCESS: config-install_hotplug ran successfully and took 0.001 seconds
2025-03-13 08:12:41,056 - modules.py[DEBUG]: Running module final_message (<module 'cloudinit.config.cc_final_message' from '/usr/lib/python3/dist-packages/cloudinit/config/cc_final_message.py'>) with frequency always
2025-03-13 08:12:41,056 - handlers.py[DEBUG]: start: modules-final/config-final_message: running config-final_message with frequency always
2025-03-13 08:12:41,056 - helpers.py[DEBUG]: Running config-final_message using lock (<cloudinit.helpers.DummyLock object at 0x7fbaae1abdc0>)
2025-03-13 08:12:41,056 - util.py[DEBUG]: Reading from /proc/uptime (quiet=False)
2025-03-13 08:12:41,056 - util.py[DEBUG]: Reading 11 bytes from /proc/uptime
2025-03-13 08:12:41,063 - log_util.py[DEBUG]: Cloud-init v. 24.4-0ubuntu1~22.04.1 finished at Thu, 13 Mar 2025 08:12:41 +0000. Datasource DataSourceAkamaiLocal.  Up 18.25 seconds
2025-03-13 08:12:41,063 - util.py[DEBUG]: Writing to /var/lib/cloud/instance/boot-finished - wb: [644] 67 bytes
2025-03-13 08:12:41,064 - handlers.py[DEBUG]: finish: modules-final/config-final_message: SUCCESS: config-final_message ran successfully and took 0.008 seconds
2025-03-13 08:12:41,064 - main.py[DEBUG]: Ran 10 modules with 0 failures
2025-03-13 08:12:41,064 - util.py[DEBUG]: Reading from /proc/uptime (quiet=False)
2025-03-13 08:12:41,064 - util.py[DEBUG]: Reading 11 bytes from /proc/uptime
2025-03-13 08:12:41,064 - atomic_helper.py[DEBUG]: Atomically writing to file /var/lib/cloud/data/status.json (via temporary file /var/lib/cloud/data/tmpnkj082he) - w: [644] 508 bytes/chars
2025-03-13 08:12:41,064 - atomic_helper.py[DEBUG]: Atomically writing to file /var/lib/cloud/data/result.json (via temporary file /var/lib/cloud/data/tmp0fb7dwef) - w: [644] 72 bytes/chars
2025-03-13 08:12:41,065 - util.py[DEBUG]: Creating symbolic link from '/run/cloud-init/result.json' => '../../var/lib/cloud/data/result.json'
2025-03-13 08:12:41,065 - performance.py[DEBUG]: cloud-init stage: 'modules-final' took 0.169 seconds
2025-03-13 08:12:41,065 - handlers.py[DEBUG]: finish: modules-final: SUCCESS: running modules for final
